<?xml version="1.0"?>
<robot xmlns:xacro="http://ros.org/wiki/xacro">
  <xacro:property name="M_PI" value="3.14159"/>
  <xacro:property name="SCALE_MM" value="0.001"/>
  <xacro:property name="SCALE_CM" value="0.01"/>

  <xacro:macro name="crane_x7_wide_two_finger_gripper"
    params="name_link_gripper_base
            name_link_gripper_finger_a
            name_link_gripper_finger_b
            name_joint_gripper_finger_a
            name_joint_gripper_finger_b
            color
            joint_velocity_limit
            joint_hand_lower_limit
            joint_hand_upper_limit">

    <link name="${name_link_gripper_base}">
      <visual>
        <origin xyz="0 0 0" rpy="0 0 0"/>
        <geometry>
          <mesh filename="package://crane_x7_description/meshes/visual/wide_two_finger_gripper_actuator.stl"
              scale="1 1 1"/>
        </geometry>
        <material name="${color}"/>
      </visual>

      <collision>
        <origin xyz="0 0 0" rpy="0 0 0"/>
        <geometry>
          <mesh filename="package://crane_x7_description/meshes/collision/wide_two_finger_gripper_actuator.stl"
              scale="1 1 1"/>
        </geometry>
      </collision>

      <inertial>
        <mass value="0.121"/>
        <origin xyz="1.08E-04 -1.03E-03 2.08E-02" rpy="0 0 0"/>
        <inertia ixx="3.20E-05" ixy="-9.45E-08" ixz="2.61E-07"
          iyy="4.14E-05" iyz="3.88E-07"
          izz="4.29E-05"/>
      </inertial>
    </link>

    <joint name="${name_joint_gripper_finger_a}" type="revolute">
      <origin xyz="-0.012 0.0 0.024" rpy="0 0 0"/>
      <axis xyz="0 -1 0"/>
      <limit effort="4.0" velocity="${joint_velocity_limit}" lower="${joint_hand_lower_limit}" upper="${joint_hand_upper_limit}"/>
      <parent link="${name_link_gripper_base}"/>
      <child link="${name_link_gripper_finger_a}"/>
      <dynamics damping="1.0e-6" friction="8.0e-1"/>
    </joint>

    <link name="${name_link_gripper_finger_a}">
      <visual>
        <origin xyz="0 0 0" rpy="${M_PI/2} 0 0"/>
        <geometry>
          <mesh filename="package://crane_x7_description/meshes/visual/wide_two_finger_gripper_finger_a.stl"
              scale="1 1 1"/>
        </geometry>
        <material name="${color}"/>
      </visual>

      <collision>
        <origin xyz="0 0 0" rpy="${M_PI/2} 0 0"/>
        <geometry>
          <mesh filename="package://crane_x7_description/meshes/collision/wide_two_finger_gripper_finger_a.stl"
              scale="1 1 1"/>
        </geometry>
      </collision>

      <inertial>
        <mass value="0.0158"/>
        <origin xyz="-2.65E-03 3.54E-03 2.69E-02" rpy="${M_PI/2} 0 0"/>
        <inertia ixx="1.01E-05" ixy="-1.97E-07" ixz="-9.89E-08"
        iyy="4.95E-06" iyz="5.37E-07"
        izz="6.24E-06"/>
      </inertial>
    </link>

    <!--Dummy joint/link to prevent error with mimic joint
    See https://github.com/ros-controls/gazebo_ros2_control/issues/173
    -->
    <joint name="${name_joint_gripper_finger_b}_mimic" type="fixed">
      <parent link="world" />
      <child link="dummy_mimic_fix" />
    </joint>
    <link name="dummy_mimic_fix"/>

    <joint name="${name_joint_gripper_finger_b}" type="revolute">
      <origin xyz="0.012 0.0 0.024" rpy="0 0 0"/>
      <axis xyz="0 1 0"/>
      <limit effort="4.0" velocity="${joint_velocity_limit}" lower="${joint_hand_lower_limit}" upper="${joint_hand_upper_limit}"/>
      <parent link="${name_link_gripper_base}"/>
      <child link="${name_link_gripper_finger_b}"/>
      <mimic joint="${name_joint_gripper_finger_a}"/>
      <dynamics damping="1.0e-6" friction="8.0e-1"/>
    </joint>

    <link name="${name_link_gripper_finger_b}">
      <visual>
        <origin xyz="0 0 0" rpy="${M_PI/2} 0 0"/>
        <geometry>
          <mesh filename="package://crane_x7_description/meshes/visual/wide_two_finger_gripper_finger_b.stl"
              scale="1 1 1"/>
        </geometry>
        <material name="${color}"/>
      </visual>

      <collision>
        <origin xyz="0 0 0" rpy="${M_PI/2} 0 0"/>
        <geometry>
          <mesh filename="package://crane_x7_description/meshes/collision/wide_two_finger_gripper_finger_b.stl"
              scale="1 1 1"/>
        </geometry>
      </collision>

      <inertial>
        <mass value="0.0139"/>
        <origin xyz="3.01E-03 2.85E-03 3.09E-02" rpy="${M_PI/2} 0 0"/>
        <inertia ixx="7.48E-06" ixy="3.61E-07" ixz="6.34E-08"
        iyy="4.09E-06" iyz="2.28E-07"
        izz="4.37E-06"/>
      </inertial>
    </link>
  </xacro:macro>
</robot>
